Workbook

Sheet Inputs
A1: Company & General Settings
A2: Business Name | B2: Example HVAC Co.
A3: Currency | B3: USD
A4: Valuation Year | B4: 2025
A6: Historical & Current Revenue
A7: Revenue - 3 Years Ago | B7: 2000000
A8: Revenue - 2 Years Ago | B8: 2000000
A9: Revenue - Last Year | B9: 2000000
A10: Revenue - Trailing 12 Months (TTM) | B10: 2000000
A11: 5-Year Revenue CAGR (optional override) | B11: 0.08
A13: Revenue Mix (TTM)
A14: Service & Repair % of Revenue | B14: 0.25
A15: New Installations % of Revenue | B15: 0.25
A16: Maintenance Contracts % of Revenue | B16: 0.25
A17: Equipment / Parts % of Revenue | B17: 0.25
A18: CHECK: Mix should sum to 100% | B18: =SUM(B14:B17)
A20: Margins & Operating Costs (Annual)
A21: Gross Margin % (on TTM Revenue) | B21: 0.45
A22: Technician & Direct Labor (annual) | B22: 250000
A23: Office/Overhead Payroll | B23: 250000
A24: Marketing & Lead Gen | B24: 250000
A25: Fleet (trucks, fuel, insurance) | B25: 250000
A26: Rent & Utilities | B26: 250000
A27: Other Operating Expenses | B27: 250000
A28: Total Operating Expenses (auto) | B28: =SUM(B22:B27)
A30: Owner Adjustments / Add-backs
A31: Owner Salary Above Market | B31: 0
A32: Personal / Non-business Expenses | B32: 0
A33: One-time / Non-recurring Costs | B33: 0
A34: Warranty Callback Reserve (negative add-back) | B34: 0
A37: Recurring Revenue & Operational Metrics
A38: Maintenance Contract Revenue (TTM) | B38: 400000
A39: Maintenance Contract Retention Rate | B39: 0.85
A40: Number of Technicians | B40: 8
A41: Number of Service Trucks | B41: 6
A42: Avg Revenue per Truck (auto) | B42: =B10/B41
A44: Balance Sheet & Asset Values
A45: Fleet (Trucks & Equipment) Market Value | B45: 400000
A46: Inventory (Parts on trucks, warehouse) | B46: 200000
A47: Other Tangible Assets | B47: 50000
...

Sheet Calculations
A1: Key Derived Metrics
A3: TTM Revenue | B3: =Inputs!B10
A4: Gross Profit | B4: =B3*Inputs!B21
A5: Gross Margin % | B5: =Inputs!B21
A6: Operating Expenses (Total) | B6: =Inputs!B28
A7: EBITDA (unadjusted) | B7: =B4-B6
A8: Total Add-backs | B8: =Inputs!B31+Inputs!B32+Inputs!B33+Inputs!B34
A9: Adjusted EBITDA | B9: =B7+B8
A10: Adjusted EBITDA Margin | B10: =IF(B3>0,B9/B3,0)
A12: Market Multiple Valuation
A13: Chosen EBITDA Multiple | B13: =Inputs!B54
A14: Enterprise Value (Multiple Method) | B14: =B9*B13
A16: Asset Floor
A17: Asset Floor Value | B17: =Inputs!B49
A19: DCF Valuation (5-Year Forecast + Terminal Value)
A21: Year | B21: Revenue | C21: Adj EBITDA Margin | D21: Adj EBITDA | E21: Discount Factor | F21: Present Value of EBITDA
A22: 1 | B22: =Inputs!B10*(1+Inputs!B56) | C22: =B10 | D22: =B22*C22 | E22: =1/(1+Inputs!B55)^1 | F22: =D22*E22
A23: 2 | B23: =B22*(1+Inputs!B56) | C23: =C22 | D23: =B23*C23 | E23: =1/(1+Inputs!B55)^2 | F23: =D23*E23
A24: 3 | B24: =B23*(1+Inputs!B56) | C24: =C22 | D24: =B24*C24 | E24: =1/(1+Inputs!B55)^3 | F24: =D24*E24
A25: 4 | B25: =B24*(1+Inputs!B56) | C25: =C22 | D25: =B25*C25 | E25: =1/(1+Inputs!B55)^4 | F25: =D25*E25
A26: 5 | B26: =B25*(1+Inputs!B56) | C26: =C22 | D26: =B26*C26 | E26: =1/(1+Inputs!B55)^5 | F26: =D26*E26
A28: Sum of PV of 5-Year EBITDA | B28: =SUM(F22:F26)
A29: Terminal Value (EBITDA_5 * Terminal Multiple) | B29: =D26*Inputs!B57
A30: PV of Terminal Value | B30: =B29*E26
A31: Enterprise Value (DCF) | B31: =B28+B30
A33: Blended Enterprise Value
A34: Weight – Market Multiple | B34: =Inputs!B58
A35: Weight – DCF | B35: =Inputs!B59
A36: Weight – Asset Floor | B36: =Inputs!B60
A37: Blended Enterprise Value | B37: =B14*B34 + B31*B35 + B17*B36
A39: Equity Value (Blended EV - Debt) | B39: =B37-Inputs!B48

Sheet Summary
A1: HVAC Business Valuation Summary
A3: Business Name | B3: =Inputs!B2
A4: TTM Revenue | B4: =Calculations!B3
A5: Adjusted EBITDA | B5: =Calculations!B9
A6: Adjusted EBITDA Margin | B6: =Calculations!B10
A8: Enterprise Value (Market Multiple) | B8: =Calculations!B14
A9: Enterprise Value (DCF) | B9: =Calculations!B31
A10: Asset Floor Value | B10: =Calculations!B17
A12: Blended Enterprise Value | B12: =Calculations!B37
A13: Debt Outstanding | B13: =Inputs!B48
A14: Equity Value (Owner's Business Value) | B14: =Calculations!B39
A16: Implied Value / Technician | B16: =IF(Inputs!B40>0,B14/Inputs!B40,0)
A17: Implied Value / Service Truck | B17: =IF(Inputs!B41>0,B14/Inputs!B41,0)
E20: Market Multiple EV | F20: =Calculations!B14
E21: DCF EV | F21: =Calculations!B31
E22: Asset Floor | F22: =Calculations!B17
E23: Blended EV | F23: =Calculations!B37
